<?xml version="1.0"?>
<!-- ======================================================================== -->
<!-- | Flexiv Rizon 10s (with blurred dynamic parameters)                   | -->
<!-- ======================================================================== -->
<robot name="rizon_with_gripper">

  <mujoco>
    <compiler 
    meshdir="../meshes" 
    balanceinertia="true" 
    discardvisual="false" 
    strippath="false" />
  </mujoco>

  <material name="rizon_light_grey">
    <color rgba="0.7 0.7 0.7 1.0" />
  </material>
  <material name="rizon_dark_grey">
    <color rgba="0.4 0.4 0.4 1.0" />
  </material>
  <material name="rizon_white">
    <color rgba="1.0 1.0 1.0 1.0" />
  </material>

  <material name="2f_85_silicone">
    <color rgba="0.1882 0.1882 0.1882 1"/>
  </material>
  <material name="2f_85_gray">
    <color rgba="0.4627 0.4627 0.4627 1"/>
  </material>
  <material name="2f_85_black">
    <color rgba="0.149 0.149 0.149 1"/>
  </material>

  <material name="green">
    <color rgba="0.0 0.8 0.0 1.0"/>
  </material>
  <material name="red">
    <color rgba="0.8 0.0 0.0 1.0"/>
  </material>

  <link name="link0">
    <inertial>
      <mass value="9.2" />
      <origin rpy="0 0 0" xyz="0.0 -0.0 0.13" />
      <inertia ixx="0.08" ixy="0.0" ixz="-0.0" iyy="0.08" iyz="0.0" izz="0.04" />
    </inertial>
    <visual name="shell-0">
      <origin rpy="0 0 0" xyz="0 0 0" />
      <geometry>
        <mesh filename="rizon10s/visual/v_link0.obj" />
      </geometry>
      <material name="rizon_dark_grey" />
    </visual>


    <!--<collision name="hull-0">-->
    <!--  <origin rpy="0 0 0" xyz="0 0 0" />-->
    <!--  <geometry>-->
    <!--    <mesh filename="rizon10s/collision/c_link0.stl" />-->
    <!--  </geometry>-->
    <!--</collision>-->

      <collision name="c_link0.stl">
      <origin rpy="-3.135731200509898 -0.0070914286865064674 1.7601452401316544" xyz="0.00032891819899692 -0.00036876907392473224 0.07876664364163569"/>
      <geometry>
        <cylinder radius="0.10828695195085732" length="0.10862981656370363"/>
      </geometry>
    </collision>

  <collision_checking><capsule name="c_link0.stl"/></collision_checking>




  </link>

  <joint name="joint_1" type="revolute">
    <parent link="link0" />
    <child link="link1" />
    <origin rpy="0.0 0.0 -3.141592653589793" xyz="0.0 0.0 0.21" />
    <axis xyz="0 0 1" />
    <limit effort="261" lower="-2.7925" upper="2.7925" velocity="1.7453" />
  </joint>

  <link name="link1">
    <inertial>
      <mass value="9.7" />
      <origin rpy="0 0 0" xyz="0.0 0.03 0.16" />
      <inertia ixx="0.18" ixy="0.0" ixz="0.0" iyy="0.17" iyz="0.02" izz="0.04" />
    </inertial>
    <visual name="shell-1">
      <origin rpy="0 0 0" xyz="0 0 0" />
      <geometry>
        <mesh filename="rizon10s/visual/v_link1.obj" />
      </geometry>
      <material name="rizon_dark_grey" />
    </visual>
    <visual name="ring-1">
      <origin rpy="0 0 0" xyz="0 0 -0.0025" />
      <geometry>
        <mesh filename="rizon10s/visual/v_ring_s1.obj"  />
      </geometry>
      <material name="rizon_white" />
    </visual>

  

   <!--<collision name="hull-1">-->
    <!--  <origin rpy="0 0 0" xyz="0 0 0" />-->
    <!--  <geometry>-->
    <!--    <mesh filename="rizon10s/collision/c_link1.stl" />-->
    <!--  </geometry>-->
    <!--</collision>-->

    <collision name="c_link1.stl">
      <origin rpy="3.1401209981186198 -0.005307839694209449 -2.6006602298211883" xyz="0.00024814527368391225 0.00029127196083683957 0.15303012648186404"/>
      <geometry>
        <cylinder radius="0.11" length="0.1820172995965973"/>
      </geometry>
    </collision>




  </link>

  <joint name="joint_2" type="revolute">
    <parent link="link1" />
    <child link="link2" />
    <origin rpy="0.0 0.0 0.0" xyz="0.0 0.0675 0.24" />
    <axis xyz="0 1 0" />
    <limit effort="261" lower="-2.6704" upper="2.6704" velocity="1.7453" />
  </joint>

  <link name="link2">
    <inertial>
      <mass value="6.56" />
      <origin rpy="0 0 0" xyz="-0.008 0.03 0.11" />
      <inertia ixx="0.1" ixy="0.0" ixz="0.0" iyy="0.08" iyz="0.02" izz="0.03" />
    </inertial>
    <visual name="shell-2">
      <origin rpy="0 0 0" xyz="0 0 0" />
      <geometry>
        <mesh filename="rizon10s/visual/v_link2.obj" />
      </geometry>
      <material name="rizon_dark_grey" />
    </visual>
    <visual name="ring-2">
      <origin rpy="1.5707963 0 0" xyz="0 -0.0025 0" />
      <geometry>
        <mesh filename="rizon10s/visual/v_ring_s2.obj"  />
      </geometry>
      <material name="rizon_white" />
    </visual>

<!-- 
    <collision name="hull-2">
      <origin rpy="0 0 0" xyz="0 0 0" />
      <geometry>
        <mesh filename="c_link2.stl" />
      </geometry>
    </collision> -->

    <collision name="c_link2.stl">
      <origin rpy="-0.04126720865260602 -0.005040524508146377 0.00010401917072817447" xyz="-0.0002424301681967157 0.05976210733104183 0.07367088388281477"/>
      <geometry>
        <cylinder radius="0.09838617557444361" length="0.1493152186350586"/>
      </geometry>
    </collision>

  <collision_checking><capsule name="c_link2.stl"/></collision_checking>





  </link>

  <joint name="joint_3" type="revolute">
    <parent link="link2" />
    <child link="link3" />
    <origin rpy="0.0 0.0 0.0" xyz="0.0 0.0625 0.2275" />
    <axis xyz="0 0 1" />
    <limit effort="123" lower="-2.7925" upper="2.7925" velocity="2.0944" />
  </joint>

  <link name="link3">
    <inertial>
      <mass value="5.45"/>
      <origin rpy="0 0 0" xyz="0.0 -0.026 0.17" />
      <inertia ixx="0.04" ixy="-0.0" ixz="-0.0" iyy="0.03" iyz="-0.01" izz="0.01" />
    </inertial>
    <visual name="shell-3">
      <origin rpy="0 0 0" xyz="0 0 0" />
      <geometry>
        <mesh filename="rizon10s/visual/v_link3.obj" />
      </geometry>
      <material name="rizon_dark_grey" />
    </visual>
    <visual name="ring-3">
      <origin rpy="0 0 0" xyz="0 0 -0.0025" />
      <geometry>
        <mesh filename="rizon10s/visual/v_ring_s3.obj"  />
      </geometry>
      <material name="rizon_white" />
    </visual>

<!-- 
    <collision name="hull-3">
      <origin rpy="0 0 0" xyz="0 0 0" />
      <geometry>
        <mesh filename="c_link3.stl" />
      </geometry>
    </collision> -->

        <collision name="c_link3.stl">
      <origin rpy="-3.110942166794248 0.012942070040906195 -0.7990266024421873" xyz="0.0009435946660551249 -0.003243672501785833 0.13776199595725278"/>
      <geometry>
        <cylinder radius="0.08133934809468238" length="0.17962829931741664"/>
      </geometry>
    </collision>

    <collision_checking><capsule name="c_link3.stl"/></collision_checking>

  
  
  
  
  </link>

  <joint name="joint_4" type="revolute">
    <parent link="link3" />
    <child link="link4" />
    <origin rpy="0.0 0.0 -3.141592653589793" xyz="0.0 -0.0625 0.2225" />
    <axis xyz="0 1 0" />
    <limit effort="123" lower="-2.7053" upper="2.7053" velocity="2.0944" />
  </joint>

  <link name="link4">
    <inertial>
      <mass value="2.906" />
      <origin rpy="0 0 0" xyz="0.013 0.047 0.101" />
      <inertia ixx="0.03" ixy="0.0" ixz="0.0" iyy="0.03" iyz="0.0" izz="0.01" />
    </inertial>
    <visual name="shell-4">
      <origin rpy="0 0 0" xyz="0 0 0" />
      <geometry>
        <mesh filename="rizon10s/visual/v_link4.obj" />
      </geometry>
      <material name="rizon_dark_grey" />
    </visual>
    <visual name="ring-4">
      <origin rpy="1.5707963 0 0" xyz="0 -0.0025 0" />
      <geometry>
        <mesh filename="rizon10s/visual/v_ring_s4.obj"  />
      </geometry>
      <material name="rizon_white" />
    </visual>

  
  
     <!--<collision name="hull-4">-->
    <!--  <origin rpy="0 0 0" xyz="0 0 0" />-->
    <!--  <geometry>-->
    <!--    <mesh filename="rizon10s/collision/c_link4.stl" />-->
    <!--  </geometry>-->
    <!--</collision>-->

    <collision name="c_link4.stl">
      <origin rpy="-0.04999599865678187 -0.0068829879926115625 0.00017209745747710214" xyz="-0.0005080457137345763 0.05393072897828459 0.06885405527591208"/>
      <geometry>
        <cylinder radius="0.08058945288499701" length="0.14050029766613556"/>
      </geometry>
    </collision>

  <collision_checking><capsule name="c_link4.stl"/></collision_checking>
  
  
  
  
  </link>

  <joint name="joint_5" type="revolute">
    <parent link="link4" />
    <child link="link5" />
    <origin rpy="0.0 0.0 -3.141592653589793" xyz="0.0 0.0575 0.205" />
    <axis xyz="0 0 1" />
    <limit effort="57" lower="-2.9671" upper="2.9671" velocity="3.8397" />
  </joint>

  <link name="link5">
    <inertial>
      <mass value="2.523" />
      <origin rpy="0 0 0" xyz="0.004 0.007 0.1309" />
      <inertia ixx="0.01" ixy="0.0" ixz="0.0" iyy="0.01" iyz="0.0" izz="0.001" />
    </inertial>
    <visual name="shell-5">
      <origin rpy="0 0 0" xyz="0 0 0" />
      <geometry>
        <mesh filename="rizon10s/visual/v_link5.obj" />
      </geometry>
      <material name="rizon_dark_grey" />
    </visual>
    <visual name="ring-5">
      <origin rpy="0 0 0" xyz="0 0 -0.0025" />
      <geometry>
        <mesh filename="rizon10s/visual/v_ring_s5.obj"  />
      </geometry>
      <material name="rizon_white" />
    </visual>





    <!--<collision name="hull-5">-->
    <!--  <origin rpy="0 0 0" xyz="0 0 0" />-->
    <!--  <geometry>-->
    <!--    <mesh filename="rizon10s/collision/c_link5.stl" />-->
    <!--  </geometry>-->
    <!--</collision>-->

    <collision name="c_link5.stl">
      <origin rpy="-3.062942439795058 0.0025142117447503054 -0.06387935132241074" xyz="0.0002143888046636051 -0.0062263048590413045 0.1148623027407365"/>
      <geometry>
        <cylinder radius="0.06321103718614053" length="0.1586607128833286"/>
      </geometry>
    </collision>

  <collision_checking><capsule name="c_link5.stl"/></collision_checking>



  
  
  
  
  
  
  </link>

  <joint name="joint_6" type="revolute">
    <parent link="link5" />
    <child link="link6" />
    <origin rpy="0.0 0.0 0.0" xyz="0.0 0.03 0.19" />
    <axis xyz="0 1 0" />
    <limit effort="57" lower="-1.3963" upper="4.5379" velocity="3.8397" />
  </joint>

  <link name="link6">
    <inertial>
      <mass value="2.426" />
      <origin rpy="0 0 0" xyz="0.02 0.057 0.066" />
      <inertia ixx="0.01" ixy="0.0" ixz="0.0" iyy="0.01" iyz="0.0" izz="0.001" />
    </inertial>
    <visual name="shell-6">
      <origin rpy="0 0 0" xyz="0 0 0" />
      <geometry>
        <mesh filename="rizon10s/visual/v_link6.obj" />
      </geometry>
      <material name="rizon_dark_grey" />
    </visual>
    <visual name="ring-6">
      <origin rpy="1.5707963 0 0" xyz="0 -0.0025 0" />
      <geometry>
        <mesh filename="rizon10s/visual/v_ring_s6.obj"  />
      </geometry>
      <material name="rizon_white" />
    </visual>




   <!--<collision name="hull-6">-->
    <!--  <origin rpy="0 0 0" xyz="0 0 0" />-->
    <!--  <geometry>-->
    <!--    <mesh filename="rizon10s/collision/c_link6.stl" />-->
    <!--  </geometry>-->
    <!--</collision>-->

    <collision name="c_link6.stl">
      <origin rpy="2.8107047832724485 -0.3512021488559727 -1.6315119697149592" xyz="0.02153718931005263 0.056258354575723396 0.059821353702356424"/>
      <geometry>
        <cylinder radius="0.07271170783548435" length="0.1132427653650164"/>
      </geometry>
    </collision>

  <collision_checking><capsule name="c_link6.stl"/></collision_checking>



  </link>

  <joint name="joint_7" type="revolute">
    <parent link="link6" />
    <child link="link7" />
    <origin rpy="0.0 -1.5707963478683205 0.0" xyz="-0.015 0.073 0.11" />
    <axis xyz="0 0 1" />
    <limit effort="57" lower="-2.9671" upper="2.9671" velocity="3.8397" />
  </joint>

  <link name="link7">
    <inertial>
      <mass value="2.9811" />
      <origin rpy="0 0 0" xyz="0.003 0.003 0.107" />
      <!--note: i changed inertia from 0.01 to 0.001 because mujoco simulation was unstable-->
      <inertia ixx="0.01" ixy="0.0" ixz="0.0" iyy="0.01" iyz="0.0" izz="0.01" />
    </inertial>
    <visual name="shell-7">
      <origin rpy="0 0 0" xyz="0 0 0" />
      <geometry>
        <mesh filename="rizon10s/visual/v_link7.obj" />
      </geometry>
      <material name="rizon_dark_grey" />
    </visual>
    <visual name="ring-7">
      <origin rpy="0 0 0" xyz="0 0 -0.0025" />
      <geometry>
        <mesh filename="rizon10s/visual/v_ring_s7.obj"  />
      </geometry>
      <material name="rizon_white" />
    </visual>



   <!--<collision name="hull-7">-->
    <!--  <origin rpy="0 0 0" xyz="0 0 0" />-->
    <!--  <geometry>-->
    <!--    <mesh filename="rizon10s/collision/c_link7.stl" />-->
    <!--  </geometry>-->
    <!--</collision>-->

    <collision name="c_link7.stl">
      <origin rpy="0.0004100094101540108 -0.0007421483351071068 -1.5214390947093648e-07" xyz="3.4338789721404413e-06 0.00010384113989505138 0.05293979816513525"/>
      <geometry>
        <cylinder radius="0.05225879509988878" length="0.08200182317353522"/>
      </geometry>
    </collision>




  </link>

  <joint name="ee_joint" type="fixed">
    <origin rpy="0.0 0.0 -1.570796326794896" xyz="0.0 0.0 0.1593" />
    <parent link="link7"/>
    <child link="2f_85_base_mount"/>
  </joint>

  <link name="2f_85_base_mount">
    <visual>
      <geometry>
        <mesh filename="gripper_s/base_mount.stl" scale="0.001 0.001 0.001"/>
      </geometry>
      <material name="2f_85_black"/>
    </visual>
    <collision>
      <geometry>
        <mesh filename="gripper_s/base_mount.stl" scale="0.001 0.001 0.001"/>
      </geometry>
    </collision>
  </link>

  <joint name="2f_85_base_joint" type="fixed">
    <origin rpy="0 0 -1.5707963" xyz="0 0 0.0038"/>
    <parent link="2f_85_base_mount"/>
    <child link="2f_85_base"/>
  </joint>

  <link name="2f_85_base">
    <visual>
      <geometry>
        <mesh filename="gripper_s/base.stl" scale="0.001 0.001 0.001"/>
      </geometry>
      <material name="2f_85_black"/>
    </visual>
    <collision>
      <geometry>
        <mesh filename="gripper_s/base.stl" scale="0.001 0.001 0.001"/>
      </geometry>
    </collision>
  </link>

  <joint name="gripper_center_joint" type="fixed">
    <origin rpy="3.141592653589793  0 3.141592653589793" xyz="0 0 0.15"/>
    <parent link="2f_85_base"/>
    <child link="gripper_center"/>
  </joint>

  <link name="gripper_center">
    <visual>
      <origin xyz="0 0 0.0"/>
      <geometry>
        <sphere radius="0.01"/>
      </geometry>
      <material name="green"/>
    </visual>
    <visual>
      <origin xyz=".1 0 0.0"/>
      <geometry>
        <sphere radius="0.01"/>
      </geometry>
      <material name="red"/>
    </visual>
  </link>

  <!-- right finger -->
  <joint name="2f_85_right_driver_joint" type="fixed">
    <origin rpy="0 0 0" xyz="0 0.0306011 0.054904"/>
    <parent link="2f_85_base"/>
    <child link="2f_85_right_driver"/>
    <axis xyz="1 0 0"/>
    <limit effort="60" lower="0.0" upper="0.834" velocity="1.91986177778"/>
  </joint>

  <link name="2f_85_right_driver">
    <visual>
      <geometry>
        <mesh filename="gripper_s/driver.stl" scale="0.001 0.001 0.001"/>
      </geometry>
      <material name="2f_85_gray"/>
    </visual>
    <collision>
      <geometry>
        <mesh filename="gripper_s/driver.stl" scale="0.001 0.001 0.001"/>
      </geometry>
    </collision>
  </link>

  <joint name="2f_85_right_coupler_joint" type="fixed">
    <origin rpy="0 0 0" xyz="0 0.0315 -0.0041"/>
    <parent link="2f_85_right_driver"/>
    <child link="2f_85_right_coupler"/>
  </joint>

  <link name="2f_85_right_coupler">
    <visual>
      <geometry>
        <mesh filename="gripper_s/coupler.stl" scale="0.001 0.001 0.001"/>
      </geometry>
      <material name="2f_85_black"/>
    </visual>
    <collision>
      <geometry>
        <mesh filename="gripper_s/coupler.stl" scale="0.001 0.001 0.001"/>
      </geometry>
    </collision>
  </link>

  <joint name="2f_85_right_follower_joint" type="fixed">
    <origin rpy="0 0 0" xyz="0 0.0061 0.0471"/>
    <parent link="2f_85_right_coupler"/>
    <child link="2f_85_right_follower"/>
    <axis xyz="1 0 0"/>
    <limit effort="176" lower="-2.96705911111" upper="2.96705911111" velocity="1.91986177778"/>
    <mimic joint="2f_85_right_driver_joint" multiplier="-1"/>
  </joint>

  <link name="2f_85_right_follower">
    <visual>
      <geometry>
        <mesh filename="gripper_s/follower.stl" scale="0.001 0.001 0.001"/>
      </geometry>
      <material name="2f_85_black"/>
    </visual>
    <collision>
      <geometry>
        <mesh filename="gripper_s/follower.stl" scale="0.001 0.001 0.001"/>
      </geometry>
    </collision>
  </link>

  <joint name="2f_85_right_pad_joint" type="fixed">
    <origin rpy="0 0 0" xyz="0 -0.0189 0.01352"/>
		<parent link="2f_85_right_follower"/>
		<child link="2f_85_right_pad"/>
	</joint>

	<link name="2f_85_right_pad">
		<visual>
			<geometry>
				<mesh filename="gripper_s/pad.stl" scale="0.001 0.001 0.001"/>
			</geometry>
      <material name="2f_85_gray"/>
		</visual>
		<collision>
			<geometry>
				<mesh filename="gripper_s/pad.stl" scale="0.001 0.001 0.001"/>
			</geometry>
		</collision>
    <visual>
			<geometry>
				<mesh filename="gripper_s/silicone_pad.stl" scale="0.001 0.001 0.001"/>
			</geometry>
      <material name="2f_85_silicone"/>
		</visual>
    <collision>
			<geometry>
				<mesh filename="gripper_s/silicone_pad.stl" scale="0.001 0.001 0.001"/>
			</geometry>
		</collision>
	</link>

  <joint name="2f_85_right_spring_link_joint" type="fixed">
    <origin rpy="0 0 0" xyz="0 0.0132 0.0609"/>
    <parent link="2f_85_base"/>
    <child link="2f_85_right_spring_link"/>
    <axis xyz="1 0 0"/>
    <limit effort="176" lower="-2.96705911111" upper="2.96705911111" velocity="1.91986177778"/>
    <mimic joint="2f_85_right_driver_joint" multiplier="1"/>
  </joint>

  <link name="2f_85_right_spring_link">
    <visual>
      <geometry>
        <mesh filename="gripper_s/spring_link.stl" scale="0.001 0.001 0.001"/>
      </geometry>
      <material name="2f_85_black"/>
    </visual>
    <collision>
      <geometry>
        <mesh filename="gripper_s/spring_link.stl" scale="0.001 0.001 0.001"/>
      </geometry>
    </collision>
  </link>

  <!-- left finger -->
  <joint name="2f_85_left_driver_joint" type="fixed">
    <origin rpy="0 0 3.141592653589793" xyz="0 -0.0306011 0.054904"/>
    <parent link="2f_85_base"/>
    <child link="2f_85_left_driver"/>
    <axis xyz="1 0 0"/>
    <limit effort="176" lower="0.0" upper="0.834" velocity="1.91986177778"/>
    <mimic joint="2f_85_right_driver_joint" multiplier="1"/>
  </joint>

  <link name="2f_85_left_driver">
    <visual>
      <geometry>
        <mesh filename="gripper_s/driver.stl" scale="0.001 0.001 0.001"/>
      </geometry>
      <material name="2f_85_gray"/>
    </visual>
    <collision>
      <geometry>
        <mesh filename="gripper_s/driver.stl" scale="0.001 0.001 0.001"/>
      </geometry>
    </collision>
  </link>

  <joint name="2f_85_left_coupler_joint" type="fixed">
    <origin rpy="0 0 0" xyz="0 0.0315 -0.0041"/>
    <parent link="2f_85_left_driver"/>
    <child link="2f_85_left_coupler"/>
  </joint>

  <link name="2f_85_left_coupler">
    <visual>
      <geometry>
        <mesh filename="gripper_s/coupler.stl" scale="0.001 0.001 0.001"/>
      </geometry>
      <material name="2f_85_black"/>
    </visual>
    <collision>
      <geometry>
        <mesh filename="gripper_s/coupler.stl" scale="0.001 0.001 0.001"/>
      </geometry>
    </collision>
  </link>

  <joint name="2f_85_left_follower_joint" type="fixed">
    <origin rpy="0 0 0" xyz="0 0.0061 0.0471"/>
    <parent link="2f_85_left_coupler"/>
    <child link="2f_85_left_follower"/>
    <axis xyz="1 0 0"/>
    <limit effort="176" lower="-2.96705911111" upper="2.96705911111" velocity="1.91986177778"/>
    <mimic joint="2f_85_right_driver_joint" multiplier="-1"/>
  </joint>

  <link name="2f_85_left_follower">
    <visual>
      <geometry>
        <mesh filename="gripper_s/follower.stl" scale="0.001 0.001 0.001"/>
      </geometry>
      <material name="2f_85_black"/>
    </visual>
    <collision>
      <geometry>
        <mesh filename="gripper_s/follower.stl" scale="0.001 0.001 0.001"/>
      </geometry>
    </collision>
  </link>

  <joint name="2f_85_left_pad_joint" type="fixed">
    <origin rpy="0 0 0" xyz="0 -0.0189 0.01352"/>
		<parent link="2f_85_left_follower"/>
		<child link="2f_85_left_pad"/>
	</joint>

	<link name="2f_85_left_pad">
		<visual>
			<geometry>
				<mesh filename="gripper_s/pad.stl" scale="0.001 0.001 0.001"/>
			</geometry>
      <material name="2f_85_gray"/>
		</visual>
		<collision>
			<geometry>
				<mesh filename="gripper_s/pad.stl" scale="0.001 0.001 0.001"/>
			</geometry>
		</collision>
    <visual>
			<geometry>
				<mesh filename="gripper_s/silicone_pad.stl" scale="0.001 0.001 0.001"/>
			</geometry>
      <material name="2f_85_silicone"/>
		</visual>
		<collision>
			<geometry>
				<mesh filename="gripper_s/silicone_pad.stl" scale="0.001 0.001 0.001"/>
			</geometry>
		</collision>
	</link>

  <joint name="2f_85_left_spring_link_joint" type="fixed">
    <origin rpy="0 0 3.141592653589793" xyz="0 -0.0132 0.0609"/>
    <parent link="2f_85_base"/>
    <child link="2f_85_left_spring_link"/>
    <axis xyz="1 0 0"/>
    <limit effort="176" lower="-2.96705911111" upper="2.96705911111" velocity="1.91986177778"/>
    <mimic joint="2f_85_right_driver_joint" multiplier="1"/>
  </joint>

  <link name="2f_85_left_spring_link">
    <visual>
      <geometry>
        <mesh filename="gripper_s/spring_link.stl" scale="0.001 0.001 0.001"/>
      </geometry>
      <material name="2f_85_black"/>
    </visual>
    <collision>
      <geometry>
        <mesh filename="gripper_s/spring_link.stl" scale="0.001 0.001 0.001"/>
      </geometry>
    </collision>
  </link>

  <joint name="link7_to_flange" type="fixed">
    <parent link="link7" />
    <child link="flange" />
    <origin rpy="0.0 0.0 -3.141592653589793" xyz="0.0 0.0 0.124" />
  </joint>

  <link name="flange" >
   <inertial>
      <mass value="0" />
      <origin rpy="0 0 0" xyz="0.0 0.0 0.057" />
      <inertia ixx="0.03" ixy="0.0" ixz="0.0" iyy="0.03" iyz="0.0" izz="0.01" />
    </inertial>
  </link>

</robot>